[2021-03-03 14:23:39,452] {scheduler_job.py:181} INFO - Started process (PID=29) to work on /opt/airflow/dags/submissions_count.py
[2021-03-03 14:23:39,471] {scheduler_job.py:629} INFO - Processing file /opt/airflow/dags/submissions_count.py for tasks to queue
[2021-03-03 14:23:39,472] {logging_mixin.py:103} INFO - [2021-03-03 14:23:39,472] {dagbag.py:440} INFO - Filling up the DagBag from /opt/airflow/dags/submissions_count.py
[2021-03-03 14:23:39,531] {logging_mixin.py:103} INFO - [2021-03-03 14:23:39,516] {dagbag.py:297} ERROR - Failed to import: /opt/airflow/dags/submissions_count.py
Traceback (most recent call last):
  File "/home/airflow/.local/lib/python3.8/site-packages/airflow/models/dagbag.py", line 294, in _load_modules_from_file
    loader.exec_module(new_module)
  File "<frozen importlib._bootstrap_external>", line 783, in exec_module
  File "<frozen importlib._bootstrap>", line 219, in _call_with_frames_removed
  File "/opt/airflow/dags/submissions_count.py", line 43, in <module>
    python_callable=update_mv(),
  File "/opt/airflow/dags/scripts/submissions_count.py", line 5, in update_mv
    conn = psycopg2.connect(dbname=os.getenv("POSTGRES_DB"),
  File "/home/airflow/.local/lib/python3.8/site-packages/psycopg2/__init__.py", line 127, in connect
    conn = _connect(dsn, connection_factory=connection_factory, **kwasync)
psycopg2.OperationalError: could not connect to server: No such file or directory
	Is the server running locally and accepting
	connections on Unix domain socket "/var/run/postgresql/.s.PGSQL.5432"?
[2021-03-03 14:23:39,531] {scheduler_job.py:641} WARNING - No viable dags retrieved from /opt/airflow/dags/submissions_count.py
[2021-03-03 14:23:39,623] {scheduler_job.py:189} INFO - Processing /opt/airflow/dags/submissions_count.py took 0.187 seconds
[2021-03-03 14:23:47,415] {scheduler_job.py:181} INFO - Started process (PID=55) to work on /opt/airflow/dags/submissions_count.py
[2021-03-03 14:23:47,434] {scheduler_job.py:629} INFO - Processing file /opt/airflow/dags/submissions_count.py for tasks to queue
[2021-03-03 14:23:47,435] {logging_mixin.py:103} INFO - [2021-03-03 14:23:47,435] {dagbag.py:440} INFO - Filling up the DagBag from /opt/airflow/dags/submissions_count.py
[2021-03-03 14:23:47,500] {logging_mixin.py:103} INFO - [2021-03-03 14:23:47,497] {dagbag.py:297} ERROR - Failed to import: /opt/airflow/dags/submissions_count.py
Traceback (most recent call last):
  File "/home/airflow/.local/lib/python3.8/site-packages/airflow/models/dagbag.py", line 294, in _load_modules_from_file
    loader.exec_module(new_module)
  File "<frozen importlib._bootstrap_external>", line 783, in exec_module
  File "<frozen importlib._bootstrap>", line 219, in _call_with_frames_removed
  File "/opt/airflow/dags/submissions_count.py", line 43, in <module>
    python_callable=update_mv(),
  File "/opt/airflow/dags/scripts/submissions_count.py", line 5, in update_mv
    conn = psycopg2.connect(dbname=os.getenv("POSTGRES_DB"),
  File "/home/airflow/.local/lib/python3.8/site-packages/psycopg2/__init__.py", line 127, in connect
    conn = _connect(dsn, connection_factory=connection_factory, **kwasync)
psycopg2.OperationalError: could not connect to server: No such file or directory
	Is the server running locally and accepting
	connections on Unix domain socket "/var/run/postgresql/.s.PGSQL.5432"?
[2021-03-03 14:23:47,518] {scheduler_job.py:641} WARNING - No viable dags retrieved from /opt/airflow/dags/submissions_count.py
[2021-03-03 14:23:47,702] {scheduler_job.py:189} INFO - Processing /opt/airflow/dags/submissions_count.py took 0.320 seconds
[2021-03-03 14:23:55,055] {scheduler_job.py:181} INFO - Started process (PID=81) to work on /opt/airflow/dags/submissions_count.py
[2021-03-03 14:23:55,081] {scheduler_job.py:629} INFO - Processing file /opt/airflow/dags/submissions_count.py for tasks to queue
[2021-03-03 14:23:55,083] {logging_mixin.py:103} INFO - [2021-03-03 14:23:55,083] {dagbag.py:440} INFO - Filling up the DagBag from /opt/airflow/dags/submissions_count.py
[2021-03-03 14:23:55,159] {logging_mixin.py:103} INFO - [2021-03-03 14:23:55,142] {dagbag.py:297} ERROR - Failed to import: /opt/airflow/dags/submissions_count.py
Traceback (most recent call last):
  File "/home/airflow/.local/lib/python3.8/site-packages/airflow/models/dagbag.py", line 294, in _load_modules_from_file
    loader.exec_module(new_module)
  File "<frozen importlib._bootstrap_external>", line 783, in exec_module
  File "<frozen importlib._bootstrap>", line 219, in _call_with_frames_removed
  File "/opt/airflow/dags/submissions_count.py", line 43, in <module>
    python_callable=update_mv(),
  File "/opt/airflow/dags/scripts/submissions_count.py", line 5, in update_mv
    conn = psycopg2.connect(dbname=os.getenv("POSTGRES_DB"),
  File "/home/airflow/.local/lib/python3.8/site-packages/psycopg2/__init__.py", line 127, in connect
    conn = _connect(dsn, connection_factory=connection_factory, **kwasync)
psycopg2.OperationalError: could not connect to server: No such file or directory
	Is the server running locally and accepting
	connections on Unix domain socket "/var/run/postgresql/.s.PGSQL.5432"?
[2021-03-03 14:23:55,160] {scheduler_job.py:641} WARNING - No viable dags retrieved from /opt/airflow/dags/submissions_count.py
[2021-03-03 14:23:55,286] {scheduler_job.py:189} INFO - Processing /opt/airflow/dags/submissions_count.py took 0.253 seconds
[2021-03-03 14:24:03,442] {scheduler_job.py:181} INFO - Started process (PID=108) to work on /opt/airflow/dags/submissions_count.py
[2021-03-03 14:24:03,444] {scheduler_job.py:629} INFO - Processing file /opt/airflow/dags/submissions_count.py for tasks to queue
[2021-03-03 14:24:03,458] {logging_mixin.py:103} INFO - [2021-03-03 14:24:03,458] {dagbag.py:440} INFO - Filling up the DagBag from /opt/airflow/dags/submissions_count.py
[2021-03-03 14:24:03,524] {logging_mixin.py:103} INFO - [2021-03-03 14:24:03,522] {dagbag.py:297} ERROR - Failed to import: /opt/airflow/dags/submissions_count.py
Traceback (most recent call last):
  File "/home/airflow/.local/lib/python3.8/site-packages/airflow/models/dagbag.py", line 294, in _load_modules_from_file
    loader.exec_module(new_module)
  File "<frozen importlib._bootstrap_external>", line 783, in exec_module
  File "<frozen importlib._bootstrap>", line 219, in _call_with_frames_removed
  File "/opt/airflow/dags/submissions_count.py", line 43, in <module>
    python_callable=update_mv(),
  File "/opt/airflow/dags/scripts/submissions_count.py", line 5, in update_mv
    conn = psycopg2.connect(dbname=os.getenv("POSTGRES_DB"),
  File "/home/airflow/.local/lib/python3.8/site-packages/psycopg2/__init__.py", line 127, in connect
    conn = _connect(dsn, connection_factory=connection_factory, **kwasync)
psycopg2.OperationalError: could not connect to server: No such file or directory
	Is the server running locally and accepting
	connections on Unix domain socket "/var/run/postgresql/.s.PGSQL.5432"?
[2021-03-03 14:24:03,525] {scheduler_job.py:641} WARNING - No viable dags retrieved from /opt/airflow/dags/submissions_count.py
[2021-03-03 14:24:03,608] {scheduler_job.py:189} INFO - Processing /opt/airflow/dags/submissions_count.py took 0.189 seconds
[2021-03-03 14:24:10,065] {scheduler_job.py:181} INFO - Started process (PID=134) to work on /opt/airflow/dags/submissions_count.py
[2021-03-03 14:24:10,068] {scheduler_job.py:629} INFO - Processing file /opt/airflow/dags/submissions_count.py for tasks to queue
[2021-03-03 14:24:10,080] {logging_mixin.py:103} INFO - [2021-03-03 14:24:10,080] {dagbag.py:440} INFO - Filling up the DagBag from /opt/airflow/dags/submissions_count.py
[2021-03-03 14:24:10,142] {logging_mixin.py:103} INFO - [2021-03-03 14:24:10,140] {dagbag.py:297} ERROR - Failed to import: /opt/airflow/dags/submissions_count.py
Traceback (most recent call last):
  File "/home/airflow/.local/lib/python3.8/site-packages/airflow/models/dagbag.py", line 294, in _load_modules_from_file
    loader.exec_module(new_module)
  File "<frozen importlib._bootstrap_external>", line 783, in exec_module
  File "<frozen importlib._bootstrap>", line 219, in _call_with_frames_removed
  File "/opt/airflow/dags/submissions_count.py", line 43, in <module>
    python_callable=update_mv(),
  File "/opt/airflow/dags/scripts/submissions_count.py", line 5, in update_mv
    conn = psycopg2.connect(dbname=os.getenv("POSTGRES_DB"),
  File "/home/airflow/.local/lib/python3.8/site-packages/psycopg2/__init__.py", line 127, in connect
    conn = _connect(dsn, connection_factory=connection_factory, **kwasync)
psycopg2.OperationalError: could not connect to server: No such file or directory
	Is the server running locally and accepting
	connections on Unix domain socket "/var/run/postgresql/.s.PGSQL.5432"?
[2021-03-03 14:24:10,143] {scheduler_job.py:641} WARNING - No viable dags retrieved from /opt/airflow/dags/submissions_count.py
[2021-03-03 14:24:10,238] {scheduler_job.py:189} INFO - Processing /opt/airflow/dags/submissions_count.py took 0.210 seconds
[2021-03-03 14:24:15,795] {scheduler_job.py:181} INFO - Started process (PID=160) to work on /opt/airflow/dags/submissions_count.py
[2021-03-03 14:24:15,804] {scheduler_job.py:629} INFO - Processing file /opt/airflow/dags/submissions_count.py for tasks to queue
[2021-03-03 14:24:15,805] {logging_mixin.py:103} INFO - [2021-03-03 14:24:15,805] {dagbag.py:440} INFO - Filling up the DagBag from /opt/airflow/dags/submissions_count.py
[2021-03-03 14:24:15,849] {logging_mixin.py:103} INFO - [2021-03-03 14:24:15,846] {dagbag.py:297} ERROR - Failed to import: /opt/airflow/dags/submissions_count.py
Traceback (most recent call last):
  File "/home/airflow/.local/lib/python3.8/site-packages/airflow/models/dagbag.py", line 294, in _load_modules_from_file
    loader.exec_module(new_module)
  File "<frozen importlib._bootstrap_external>", line 783, in exec_module
  File "<frozen importlib._bootstrap>", line 219, in _call_with_frames_removed
  File "/opt/airflow/dags/submissions_count.py", line 43, in <module>
    python_callable=update_mv(),
  File "/opt/airflow/dags/scripts/submissions_count.py", line 5, in update_mv
    conn = psycopg2.connect(dbname=os.getenv("POSTGRES_DB"),
  File "/home/airflow/.local/lib/python3.8/site-packages/psycopg2/__init__.py", line 127, in connect
    conn = _connect(dsn, connection_factory=connection_factory, **kwasync)
psycopg2.OperationalError: could not connect to server: No such file or directory
	Is the server running locally and accepting
	connections on Unix domain socket "/var/run/postgresql/.s.PGSQL.5432"?
[2021-03-03 14:24:15,849] {scheduler_job.py:641} WARNING - No viable dags retrieved from /opt/airflow/dags/submissions_count.py
[2021-03-03 14:24:15,921] {scheduler_job.py:189} INFO - Processing /opt/airflow/dags/submissions_count.py took 0.179 seconds
[2021-03-03 14:24:22,257] {scheduler_job.py:181} INFO - Started process (PID=186) to work on /opt/airflow/dags/submissions_count.py
[2021-03-03 14:24:22,260] {scheduler_job.py:629} INFO - Processing file /opt/airflow/dags/submissions_count.py for tasks to queue
[2021-03-03 14:24:22,269] {logging_mixin.py:103} INFO - [2021-03-03 14:24:22,269] {dagbag.py:440} INFO - Filling up the DagBag from /opt/airflow/dags/submissions_count.py
[2021-03-03 14:24:22,307] {logging_mixin.py:103} INFO - [2021-03-03 14:24:22,298] {dagbag.py:297} ERROR - Failed to import: /opt/airflow/dags/submissions_count.py
Traceback (most recent call last):
  File "/home/airflow/.local/lib/python3.8/site-packages/airflow/models/dagbag.py", line 294, in _load_modules_from_file
    loader.exec_module(new_module)
  File "<frozen importlib._bootstrap_external>", line 783, in exec_module
  File "<frozen importlib._bootstrap>", line 219, in _call_with_frames_removed
  File "/opt/airflow/dags/submissions_count.py", line 43, in <module>
    python_callable=update_mv(),
  File "/opt/airflow/dags/scripts/submissions_count.py", line 5, in update_mv
    conn = psycopg2.connect(dbname=os.getenv("POSTGRES_DB"),
  File "/home/airflow/.local/lib/python3.8/site-packages/psycopg2/__init__.py", line 127, in connect
    conn = _connect(dsn, connection_factory=connection_factory, **kwasync)
psycopg2.OperationalError: could not connect to server: No such file or directory
	Is the server running locally and accepting
	connections on Unix domain socket "/var/run/postgresql/.s.PGSQL.5432"?
[2021-03-03 14:24:22,308] {scheduler_job.py:641} WARNING - No viable dags retrieved from /opt/airflow/dags/submissions_count.py
[2021-03-03 14:24:22,438] {scheduler_job.py:189} INFO - Processing /opt/airflow/dags/submissions_count.py took 0.193 seconds
[2021-03-03 14:24:28,203] {scheduler_job.py:181} INFO - Started process (PID=212) to work on /opt/airflow/dags/submissions_count.py
[2021-03-03 14:24:28,209] {scheduler_job.py:629} INFO - Processing file /opt/airflow/dags/submissions_count.py for tasks to queue
[2021-03-03 14:24:28,211] {logging_mixin.py:103} INFO - [2021-03-03 14:24:28,211] {dagbag.py:440} INFO - Filling up the DagBag from /opt/airflow/dags/submissions_count.py
[2021-03-03 14:24:28,277] {logging_mixin.py:103} INFO - [2021-03-03 14:24:28,267] {dagbag.py:297} ERROR - Failed to import: /opt/airflow/dags/submissions_count.py
Traceback (most recent call last):
  File "/home/airflow/.local/lib/python3.8/site-packages/airflow/models/dagbag.py", line 294, in _load_modules_from_file
    loader.exec_module(new_module)
  File "<frozen importlib._bootstrap_external>", line 783, in exec_module
  File "<frozen importlib._bootstrap>", line 219, in _call_with_frames_removed
  File "/opt/airflow/dags/submissions_count.py", line 43, in <module>
    python_callable=update_mv(),
  File "/opt/airflow/dags/scripts/submissions_count.py", line 5, in update_mv
    conn = psycopg2.connect(dbname=os.getenv("POSTGRES_DB"),
  File "/home/airflow/.local/lib/python3.8/site-packages/psycopg2/__init__.py", line 127, in connect
    conn = _connect(dsn, connection_factory=connection_factory, **kwasync)
psycopg2.OperationalError: could not connect to server: No such file or directory
	Is the server running locally and accepting
	connections on Unix domain socket "/var/run/postgresql/.s.PGSQL.5432"?
[2021-03-03 14:24:28,278] {scheduler_job.py:641} WARNING - No viable dags retrieved from /opt/airflow/dags/submissions_count.py
[2021-03-03 14:24:28,337] {scheduler_job.py:189} INFO - Processing /opt/airflow/dags/submissions_count.py took 0.149 seconds
[2021-03-03 14:24:33,778] {scheduler_job.py:181} INFO - Started process (PID=238) to work on /opt/airflow/dags/submissions_count.py
[2021-03-03 14:24:33,780] {scheduler_job.py:629} INFO - Processing file /opt/airflow/dags/submissions_count.py for tasks to queue
[2021-03-03 14:24:33,784] {logging_mixin.py:103} INFO - [2021-03-03 14:24:33,783] {dagbag.py:440} INFO - Filling up the DagBag from /opt/airflow/dags/submissions_count.py
[2021-03-03 14:24:33,810] {logging_mixin.py:103} INFO - [2021-03-03 14:24:33,800] {dagbag.py:297} ERROR - Failed to import: /opt/airflow/dags/submissions_count.py
Traceback (most recent call last):
  File "/home/airflow/.local/lib/python3.8/site-packages/airflow/models/dagbag.py", line 294, in _load_modules_from_file
    loader.exec_module(new_module)
  File "<frozen importlib._bootstrap_external>", line 783, in exec_module
  File "<frozen importlib._bootstrap>", line 219, in _call_with_frames_removed
  File "/opt/airflow/dags/submissions_count.py", line 43, in <module>
    python_callable=update_mv(),
  File "/opt/airflow/dags/scripts/submissions_count.py", line 5, in update_mv
    conn = psycopg2.connect(dbname=os.getenv("POSTGRES_DB"),
  File "/home/airflow/.local/lib/python3.8/site-packages/psycopg2/__init__.py", line 127, in connect
    conn = _connect(dsn, connection_factory=connection_factory, **kwasync)
psycopg2.OperationalError: could not connect to server: No such file or directory
	Is the server running locally and accepting
	connections on Unix domain socket "/var/run/postgresql/.s.PGSQL.5432"?
[2021-03-03 14:24:33,811] {scheduler_job.py:641} WARNING - No viable dags retrieved from /opt/airflow/dags/submissions_count.py
[2021-03-03 14:24:33,930] {scheduler_job.py:189} INFO - Processing /opt/airflow/dags/submissions_count.py took 0.174 seconds
[2021-03-03 14:24:40,535] {scheduler_job.py:181} INFO - Started process (PID=264) to work on /opt/airflow/dags/submissions_count.py
[2021-03-03 14:24:40,538] {scheduler_job.py:629} INFO - Processing file /opt/airflow/dags/submissions_count.py for tasks to queue
[2021-03-03 14:24:40,539] {logging_mixin.py:103} INFO - [2021-03-03 14:24:40,539] {dagbag.py:440} INFO - Filling up the DagBag from /opt/airflow/dags/submissions_count.py
[2021-03-03 14:24:40,587] {logging_mixin.py:103} INFO - [2021-03-03 14:24:40,584] {dagbag.py:297} ERROR - Failed to import: /opt/airflow/dags/submissions_count.py
Traceback (most recent call last):
  File "/home/airflow/.local/lib/python3.8/site-packages/airflow/models/dagbag.py", line 294, in _load_modules_from_file
    loader.exec_module(new_module)
  File "<frozen importlib._bootstrap_external>", line 783, in exec_module
  File "<frozen importlib._bootstrap>", line 219, in _call_with_frames_removed
  File "/opt/airflow/dags/submissions_count.py", line 43, in <module>
    python_callable=update_mv(),
  File "/opt/airflow/dags/scripts/submissions_count.py", line 5, in update_mv
    conn = psycopg2.connect(dbname=os.getenv("POSTGRES_DB"),
  File "/home/airflow/.local/lib/python3.8/site-packages/psycopg2/__init__.py", line 127, in connect
    conn = _connect(dsn, connection_factory=connection_factory, **kwasync)
psycopg2.OperationalError: could not connect to server: No such file or directory
	Is the server running locally and accepting
	connections on Unix domain socket "/var/run/postgresql/.s.PGSQL.5432"?
[2021-03-03 14:24:40,588] {scheduler_job.py:641} WARNING - No viable dags retrieved from /opt/airflow/dags/submissions_count.py
[2021-03-03 14:24:40,690] {scheduler_job.py:189} INFO - Processing /opt/airflow/dags/submissions_count.py took 0.198 seconds
[2021-03-03 14:24:46,916] {scheduler_job.py:181} INFO - Started process (PID=290) to work on /opt/airflow/dags/submissions_count.py
[2021-03-03 14:24:46,918] {scheduler_job.py:629} INFO - Processing file /opt/airflow/dags/submissions_count.py for tasks to queue
[2021-03-03 14:24:46,919] {logging_mixin.py:103} INFO - [2021-03-03 14:24:46,919] {dagbag.py:440} INFO - Filling up the DagBag from /opt/airflow/dags/submissions_count.py
[2021-03-03 14:24:46,986] {logging_mixin.py:103} INFO - [2021-03-03 14:24:46,975] {dagbag.py:297} ERROR - Failed to import: /opt/airflow/dags/submissions_count.py
Traceback (most recent call last):
  File "/home/airflow/.local/lib/python3.8/site-packages/airflow/models/dagbag.py", line 294, in _load_modules_from_file
    loader.exec_module(new_module)
  File "<frozen importlib._bootstrap_external>", line 783, in exec_module
  File "<frozen importlib._bootstrap>", line 219, in _call_with_frames_removed
  File "/opt/airflow/dags/submissions_count.py", line 43, in <module>
    python_callable=update_mv(),
  File "/opt/airflow/dags/scripts/submissions_count.py", line 5, in update_mv
    conn = psycopg2.connect(dbname=os.getenv("POSTGRES_DB"),
  File "/home/airflow/.local/lib/python3.8/site-packages/psycopg2/__init__.py", line 127, in connect
    conn = _connect(dsn, connection_factory=connection_factory, **kwasync)
psycopg2.OperationalError: could not connect to server: No such file or directory
	Is the server running locally and accepting
	connections on Unix domain socket "/var/run/postgresql/.s.PGSQL.5432"?
[2021-03-03 14:24:46,987] {scheduler_job.py:641} WARNING - No viable dags retrieved from /opt/airflow/dags/submissions_count.py
[2021-03-03 14:24:47,106] {scheduler_job.py:189} INFO - Processing /opt/airflow/dags/submissions_count.py took 0.222 seconds
[2021-03-03 14:24:53,304] {scheduler_job.py:181} INFO - Started process (PID=316) to work on /opt/airflow/dags/submissions_count.py
[2021-03-03 14:24:53,314] {scheduler_job.py:629} INFO - Processing file /opt/airflow/dags/submissions_count.py for tasks to queue
[2021-03-03 14:24:53,315] {logging_mixin.py:103} INFO - [2021-03-03 14:24:53,315] {dagbag.py:440} INFO - Filling up the DagBag from /opt/airflow/dags/submissions_count.py
[2021-03-03 14:24:53,371] {logging_mixin.py:103} INFO - [2021-03-03 14:24:53,359] {dagbag.py:297} ERROR - Failed to import: /opt/airflow/dags/submissions_count.py
Traceback (most recent call last):
  File "/home/airflow/.local/lib/python3.8/site-packages/airflow/models/dagbag.py", line 294, in _load_modules_from_file
    loader.exec_module(new_module)
  File "<frozen importlib._bootstrap_external>", line 783, in exec_module
  File "<frozen importlib._bootstrap>", line 219, in _call_with_frames_removed
  File "/opt/airflow/dags/submissions_count.py", line 43, in <module>
    python_callable=update_mv(),
  File "/opt/airflow/dags/scripts/submissions_count.py", line 5, in update_mv
    conn = psycopg2.connect(dbname=os.getenv("POSTGRES_DB"),
  File "/home/airflow/.local/lib/python3.8/site-packages/psycopg2/__init__.py", line 127, in connect
    conn = _connect(dsn, connection_factory=connection_factory, **kwasync)
psycopg2.OperationalError: could not connect to server: No such file or directory
	Is the server running locally and accepting
	connections on Unix domain socket "/var/run/postgresql/.s.PGSQL.5432"?
[2021-03-03 14:24:53,371] {scheduler_job.py:641} WARNING - No viable dags retrieved from /opt/airflow/dags/submissions_count.py
[2021-03-03 14:24:53,450] {scheduler_job.py:189} INFO - Processing /opt/airflow/dags/submissions_count.py took 0.165 seconds
[2021-03-03 14:24:59,594] {scheduler_job.py:181} INFO - Started process (PID=342) to work on /opt/airflow/dags/submissions_count.py
[2021-03-03 14:24:59,596] {scheduler_job.py:629} INFO - Processing file /opt/airflow/dags/submissions_count.py for tasks to queue
[2021-03-03 14:24:59,598] {logging_mixin.py:103} INFO - [2021-03-03 14:24:59,598] {dagbag.py:440} INFO - Filling up the DagBag from /opt/airflow/dags/submissions_count.py
[2021-03-03 14:24:59,693] {logging_mixin.py:103} INFO - [2021-03-03 14:24:59,691] {dagbag.py:297} ERROR - Failed to import: /opt/airflow/dags/submissions_count.py
Traceback (most recent call last):
  File "/home/airflow/.local/lib/python3.8/site-packages/airflow/models/dagbag.py", line 294, in _load_modules_from_file
    loader.exec_module(new_module)
  File "<frozen importlib._bootstrap_external>", line 783, in exec_module
  File "<frozen importlib._bootstrap>", line 219, in _call_with_frames_removed
  File "/opt/airflow/dags/submissions_count.py", line 43, in <module>
    python_callable=update_mv(),
  File "/opt/airflow/dags/scripts/submissions_count.py", line 5, in update_mv
    conn = psycopg2.connect(dbname=os.getenv("POSTGRES_DB"),
  File "/home/airflow/.local/lib/python3.8/site-packages/psycopg2/__init__.py", line 127, in connect
    conn = _connect(dsn, connection_factory=connection_factory, **kwasync)
psycopg2.OperationalError: could not connect to server: No such file or directory
	Is the server running locally and accepting
	connections on Unix domain socket "/var/run/postgresql/.s.PGSQL.5432"?
[2021-03-03 14:24:59,694] {scheduler_job.py:641} WARNING - No viable dags retrieved from /opt/airflow/dags/submissions_count.py
[2021-03-03 14:24:59,858] {scheduler_job.py:189} INFO - Processing /opt/airflow/dags/submissions_count.py took 0.303 seconds
[2021-03-03 14:25:05,308] {scheduler_job.py:181} INFO - Started process (PID=368) to work on /opt/airflow/dags/submissions_count.py
[2021-03-03 14:25:05,314] {scheduler_job.py:629} INFO - Processing file /opt/airflow/dags/submissions_count.py for tasks to queue
[2021-03-03 14:25:05,315] {logging_mixin.py:103} INFO - [2021-03-03 14:25:05,315] {dagbag.py:440} INFO - Filling up the DagBag from /opt/airflow/dags/submissions_count.py
[2021-03-03 14:25:05,367] {logging_mixin.py:103} INFO - [2021-03-03 14:25:05,365] {dagbag.py:297} ERROR - Failed to import: /opt/airflow/dags/submissions_count.py
Traceback (most recent call last):
  File "/home/airflow/.local/lib/python3.8/site-packages/airflow/models/dagbag.py", line 294, in _load_modules_from_file
    loader.exec_module(new_module)
  File "<frozen importlib._bootstrap_external>", line 783, in exec_module
  File "<frozen importlib._bootstrap>", line 219, in _call_with_frames_removed
  File "/opt/airflow/dags/submissions_count.py", line 43, in <module>
    python_callable=update_mv(),
  File "/opt/airflow/dags/scripts/submissions_count.py", line 5, in update_mv
    conn = psycopg2.connect(dbname=os.getenv("POSTGRES_DB"),
  File "/home/airflow/.local/lib/python3.8/site-packages/psycopg2/__init__.py", line 127, in connect
    conn = _connect(dsn, connection_factory=connection_factory, **kwasync)
psycopg2.OperationalError: could not connect to server: No such file or directory
	Is the server running locally and accepting
	connections on Unix domain socket "/var/run/postgresql/.s.PGSQL.5432"?
[2021-03-03 14:25:05,368] {scheduler_job.py:641} WARNING - No viable dags retrieved from /opt/airflow/dags/submissions_count.py
[2021-03-03 14:25:05,433] {scheduler_job.py:189} INFO - Processing /opt/airflow/dags/submissions_count.py took 0.136 seconds
[2021-03-03 14:25:10,502] {scheduler_job.py:181} INFO - Started process (PID=394) to work on /opt/airflow/dags/submissions_count.py
[2021-03-03 14:25:10,504] {scheduler_job.py:629} INFO - Processing file /opt/airflow/dags/submissions_count.py for tasks to queue
[2021-03-03 14:25:10,506] {logging_mixin.py:103} INFO - [2021-03-03 14:25:10,506] {dagbag.py:440} INFO - Filling up the DagBag from /opt/airflow/dags/submissions_count.py
[2021-03-03 14:25:10,540] {logging_mixin.py:103} INFO - [2021-03-03 14:25:10,538] {dagbag.py:297} ERROR - Failed to import: /opt/airflow/dags/submissions_count.py
Traceback (most recent call last):
  File "/home/airflow/.local/lib/python3.8/site-packages/airflow/models/dagbag.py", line 294, in _load_modules_from_file
    loader.exec_module(new_module)
  File "<frozen importlib._bootstrap_external>", line 783, in exec_module
  File "<frozen importlib._bootstrap>", line 219, in _call_with_frames_removed
  File "/opt/airflow/dags/submissions_count.py", line 43, in <module>
    python_callable=update_mv(),
  File "/opt/airflow/dags/scripts/submissions_count.py", line 5, in update_mv
    conn = psycopg2.connect(dbname=os.getenv("POSTGRES_DB"),
  File "/home/airflow/.local/lib/python3.8/site-packages/psycopg2/__init__.py", line 127, in connect
    conn = _connect(dsn, connection_factory=connection_factory, **kwasync)
psycopg2.OperationalError: could not connect to server: No such file or directory
	Is the server running locally and accepting
	connections on Unix domain socket "/var/run/postgresql/.s.PGSQL.5432"?
[2021-03-03 14:25:10,549] {scheduler_job.py:641} WARNING - No viable dags retrieved from /opt/airflow/dags/submissions_count.py
[2021-03-03 14:25:10,675] {scheduler_job.py:189} INFO - Processing /opt/airflow/dags/submissions_count.py took 0.192 seconds
[2021-03-03 14:25:15,459] {scheduler_job.py:181} INFO - Started process (PID=420) to work on /opt/airflow/dags/submissions_count.py
[2021-03-03 14:25:15,474] {scheduler_job.py:629} INFO - Processing file /opt/airflow/dags/submissions_count.py for tasks to queue
[2021-03-03 14:25:15,475] {logging_mixin.py:103} INFO - [2021-03-03 14:25:15,475] {dagbag.py:440} INFO - Filling up the DagBag from /opt/airflow/dags/submissions_count.py
[2021-03-03 14:25:15,549] {logging_mixin.py:103} INFO - [2021-03-03 14:25:15,547] {dagbag.py:297} ERROR - Failed to import: /opt/airflow/dags/submissions_count.py
Traceback (most recent call last):
  File "/home/airflow/.local/lib/python3.8/site-packages/airflow/models/dagbag.py", line 294, in _load_modules_from_file
    loader.exec_module(new_module)
  File "<frozen importlib._bootstrap_external>", line 783, in exec_module
  File "<frozen importlib._bootstrap>", line 219, in _call_with_frames_removed
  File "/opt/airflow/dags/submissions_count.py", line 43, in <module>
    python_callable=update_mv(),
  File "/opt/airflow/dags/scripts/submissions_count.py", line 5, in update_mv
    conn = psycopg2.connect(dbname=os.getenv("POSTGRES_DB"),
  File "/home/airflow/.local/lib/python3.8/site-packages/psycopg2/__init__.py", line 127, in connect
    conn = _connect(dsn, connection_factory=connection_factory, **kwasync)
psycopg2.OperationalError: could not connect to server: No such file or directory
	Is the server running locally and accepting
	connections on Unix domain socket "/var/run/postgresql/.s.PGSQL.5432"?
[2021-03-03 14:25:15,550] {scheduler_job.py:641} WARNING - No viable dags retrieved from /opt/airflow/dags/submissions_count.py
[2021-03-03 14:25:15,634] {scheduler_job.py:189} INFO - Processing /opt/airflow/dags/submissions_count.py took 0.198 seconds
[2021-03-03 14:25:22,163] {scheduler_job.py:181} INFO - Started process (PID=446) to work on /opt/airflow/dags/submissions_count.py
[2021-03-03 14:25:22,177] {scheduler_job.py:629} INFO - Processing file /opt/airflow/dags/submissions_count.py for tasks to queue
[2021-03-03 14:25:22,179] {logging_mixin.py:103} INFO - [2021-03-03 14:25:22,178] {dagbag.py:440} INFO - Filling up the DagBag from /opt/airflow/dags/submissions_count.py
[2021-03-03 14:25:22,260] {logging_mixin.py:103} INFO - [2021-03-03 14:25:22,258] {dagbag.py:297} ERROR - Failed to import: /opt/airflow/dags/submissions_count.py
Traceback (most recent call last):
  File "/home/airflow/.local/lib/python3.8/site-packages/airflow/models/dagbag.py", line 294, in _load_modules_from_file
    loader.exec_module(new_module)
  File "<frozen importlib._bootstrap_external>", line 783, in exec_module
  File "<frozen importlib._bootstrap>", line 219, in _call_with_frames_removed
  File "/opt/airflow/dags/submissions_count.py", line 43, in <module>
    python_callable=update_mv(),
  File "/opt/airflow/dags/scripts/submissions_count.py", line 5, in update_mv
    conn = psycopg2.connect(dbname=os.getenv("POSTGRES_DB"),
  File "/home/airflow/.local/lib/python3.8/site-packages/psycopg2/__init__.py", line 127, in connect
    conn = _connect(dsn, connection_factory=connection_factory, **kwasync)
psycopg2.OperationalError: could not connect to server: No such file or directory
	Is the server running locally and accepting
	connections on Unix domain socket "/var/run/postgresql/.s.PGSQL.5432"?
[2021-03-03 14:25:22,279] {scheduler_job.py:641} WARNING - No viable dags retrieved from /opt/airflow/dags/submissions_count.py
[2021-03-03 14:25:22,382] {scheduler_job.py:189} INFO - Processing /opt/airflow/dags/submissions_count.py took 0.244 seconds
[2021-03-03 14:25:28,075] {scheduler_job.py:181} INFO - Started process (PID=472) to work on /opt/airflow/dags/submissions_count.py
[2021-03-03 14:25:28,085] {scheduler_job.py:629} INFO - Processing file /opt/airflow/dags/submissions_count.py for tasks to queue
[2021-03-03 14:25:28,088] {logging_mixin.py:103} INFO - [2021-03-03 14:25:28,088] {dagbag.py:440} INFO - Filling up the DagBag from /opt/airflow/dags/submissions_count.py
[2021-03-03 14:25:28,153] {logging_mixin.py:103} INFO - [2021-03-03 14:25:28,142] {dagbag.py:297} ERROR - Failed to import: /opt/airflow/dags/submissions_count.py
Traceback (most recent call last):
  File "/home/airflow/.local/lib/python3.8/site-packages/airflow/models/dagbag.py", line 294, in _load_modules_from_file
    loader.exec_module(new_module)
  File "<frozen importlib._bootstrap_external>", line 783, in exec_module
  File "<frozen importlib._bootstrap>", line 219, in _call_with_frames_removed
  File "/opt/airflow/dags/submissions_count.py", line 43, in <module>
    python_callable=update_mv(),
  File "/opt/airflow/dags/scripts/submissions_count.py", line 5, in update_mv
    conn = psycopg2.connect(dbname=os.getenv("POSTGRES_DB"),
  File "/home/airflow/.local/lib/python3.8/site-packages/psycopg2/__init__.py", line 127, in connect
    conn = _connect(dsn, connection_factory=connection_factory, **kwasync)
psycopg2.OperationalError: could not connect to server: No such file or directory
	Is the server running locally and accepting
	connections on Unix domain socket "/var/run/postgresql/.s.PGSQL.5432"?
[2021-03-03 14:25:28,154] {scheduler_job.py:641} WARNING - No viable dags retrieved from /opt/airflow/dags/submissions_count.py
[2021-03-03 14:25:28,238] {scheduler_job.py:189} INFO - Processing /opt/airflow/dags/submissions_count.py took 0.199 seconds
[2021-03-03 14:25:35,466] {scheduler_job.py:181} INFO - Started process (PID=498) to work on /opt/airflow/dags/submissions_count.py
[2021-03-03 14:25:35,468] {scheduler_job.py:629} INFO - Processing file /opt/airflow/dags/submissions_count.py for tasks to queue
[2021-03-03 14:25:35,482] {logging_mixin.py:103} INFO - [2021-03-03 14:25:35,469] {dagbag.py:440} INFO - Filling up the DagBag from /opt/airflow/dags/submissions_count.py
[2021-03-03 14:25:35,516] {logging_mixin.py:103} INFO - [2021-03-03 14:25:35,514] {dagbag.py:297} ERROR - Failed to import: /opt/airflow/dags/submissions_count.py
Traceback (most recent call last):
  File "/home/airflow/.local/lib/python3.8/site-packages/airflow/models/dagbag.py", line 294, in _load_modules_from_file
    loader.exec_module(new_module)
  File "<frozen importlib._bootstrap_external>", line 783, in exec_module
  File "<frozen importlib._bootstrap>", line 219, in _call_with_frames_removed
  File "/opt/airflow/dags/submissions_count.py", line 43, in <module>
    python_callable=update_mv(),
  File "/opt/airflow/dags/scripts/submissions_count.py", line 5, in update_mv
    conn = psycopg2.connect(dbname=os.getenv("POSTGRES_DB"),
  File "/home/airflow/.local/lib/python3.8/site-packages/psycopg2/__init__.py", line 127, in connect
    conn = _connect(dsn, connection_factory=connection_factory, **kwasync)
psycopg2.OperationalError: could not connect to server: No such file or directory
	Is the server running locally and accepting
	connections on Unix domain socket "/var/run/postgresql/.s.PGSQL.5432"?
[2021-03-03 14:25:35,521] {scheduler_job.py:641} WARNING - No viable dags retrieved from /opt/airflow/dags/submissions_count.py
[2021-03-03 14:25:35,704] {scheduler_job.py:189} INFO - Processing /opt/airflow/dags/submissions_count.py took 0.296 seconds
[2021-03-03 14:25:42,197] {scheduler_job.py:181} INFO - Started process (PID=524) to work on /opt/airflow/dags/submissions_count.py
[2021-03-03 14:25:42,199] {scheduler_job.py:629} INFO - Processing file /opt/airflow/dags/submissions_count.py for tasks to queue
[2021-03-03 14:25:42,214] {logging_mixin.py:103} INFO - [2021-03-03 14:25:42,200] {dagbag.py:440} INFO - Filling up the DagBag from /opt/airflow/dags/submissions_count.py
[2021-03-03 14:25:42,267] {logging_mixin.py:103} INFO - [2021-03-03 14:25:42,257] {dagbag.py:297} ERROR - Failed to import: /opt/airflow/dags/submissions_count.py
Traceback (most recent call last):
  File "/home/airflow/.local/lib/python3.8/site-packages/airflow/models/dagbag.py", line 294, in _load_modules_from_file
    loader.exec_module(new_module)
  File "<frozen importlib._bootstrap_external>", line 783, in exec_module
  File "<frozen importlib._bootstrap>", line 219, in _call_with_frames_removed
  File "/opt/airflow/dags/submissions_count.py", line 43, in <module>
    python_callable=update_mv(),
  File "/opt/airflow/dags/scripts/submissions_count.py", line 5, in update_mv
    conn = psycopg2.connect(dbname=os.getenv("POSTGRES_DB"),
  File "/home/airflow/.local/lib/python3.8/site-packages/psycopg2/__init__.py", line 127, in connect
    conn = _connect(dsn, connection_factory=connection_factory, **kwasync)
psycopg2.OperationalError: could not connect to server: No such file or directory
	Is the server running locally and accepting
	connections on Unix domain socket "/var/run/postgresql/.s.PGSQL.5432"?
[2021-03-03 14:25:42,268] {scheduler_job.py:641} WARNING - No viable dags retrieved from /opt/airflow/dags/submissions_count.py
[2021-03-03 14:25:42,343] {scheduler_job.py:189} INFO - Processing /opt/airflow/dags/submissions_count.py took 0.165 seconds
[2021-03-03 14:25:47,681] {scheduler_job.py:181} INFO - Started process (PID=550) to work on /opt/airflow/dags/submissions_count.py
[2021-03-03 14:25:47,684] {scheduler_job.py:629} INFO - Processing file /opt/airflow/dags/submissions_count.py for tasks to queue
[2021-03-03 14:25:47,685] {logging_mixin.py:103} INFO - [2021-03-03 14:25:47,685] {dagbag.py:440} INFO - Filling up the DagBag from /opt/airflow/dags/submissions_count.py
[2021-03-03 14:25:47,717] {logging_mixin.py:103} INFO - [2021-03-03 14:25:47,709] {dagbag.py:297} ERROR - Failed to import: /opt/airflow/dags/submissions_count.py
Traceback (most recent call last):
  File "/home/airflow/.local/lib/python3.8/site-packages/airflow/models/dagbag.py", line 294, in _load_modules_from_file
    loader.exec_module(new_module)
  File "<frozen importlib._bootstrap_external>", line 783, in exec_module
  File "<frozen importlib._bootstrap>", line 219, in _call_with_frames_removed
  File "/opt/airflow/dags/submissions_count.py", line 43, in <module>
    python_callable=update_mv(),
  File "/opt/airflow/dags/scripts/submissions_count.py", line 5, in update_mv
    conn = psycopg2.connect(dbname=os.getenv("POSTGRES_DB"),
  File "/home/airflow/.local/lib/python3.8/site-packages/psycopg2/__init__.py", line 127, in connect
    conn = _connect(dsn, connection_factory=connection_factory, **kwasync)
psycopg2.OperationalError: could not connect to server: No such file or directory
	Is the server running locally and accepting
	connections on Unix domain socket "/var/run/postgresql/.s.PGSQL.5432"?
[2021-03-03 14:25:47,717] {scheduler_job.py:641} WARNING - No viable dags retrieved from /opt/airflow/dags/submissions_count.py
[2021-03-03 14:25:47,772] {scheduler_job.py:189} INFO - Processing /opt/airflow/dags/submissions_count.py took 0.106 seconds
[2021-03-03 14:25:53,462] {scheduler_job.py:181} INFO - Started process (PID=576) to work on /opt/airflow/dags/submissions_count.py
[2021-03-03 14:25:53,473] {scheduler_job.py:629} INFO - Processing file /opt/airflow/dags/submissions_count.py for tasks to queue
[2021-03-03 14:25:53,474] {logging_mixin.py:103} INFO - [2021-03-03 14:25:53,474] {dagbag.py:440} INFO - Filling up the DagBag from /opt/airflow/dags/submissions_count.py
[2021-03-03 14:25:53,512] {logging_mixin.py:103} INFO - [2021-03-03 14:25:53,510] {dagbag.py:297} ERROR - Failed to import: /opt/airflow/dags/submissions_count.py
Traceback (most recent call last):
  File "/home/airflow/.local/lib/python3.8/site-packages/airflow/models/dagbag.py", line 294, in _load_modules_from_file
    loader.exec_module(new_module)
  File "<frozen importlib._bootstrap_external>", line 783, in exec_module
  File "<frozen importlib._bootstrap>", line 219, in _call_with_frames_removed
  File "/opt/airflow/dags/submissions_count.py", line 43, in <module>
    python_callable=update_mv(),
  File "/opt/airflow/dags/scripts/submissions_count.py", line 5, in update_mv
    conn = psycopg2.connect(dbname=os.getenv("POSTGRES_DB"),
  File "/home/airflow/.local/lib/python3.8/site-packages/psycopg2/__init__.py", line 127, in connect
    conn = _connect(dsn, connection_factory=connection_factory, **kwasync)
psycopg2.OperationalError: could not connect to server: No such file or directory
	Is the server running locally and accepting
	connections on Unix domain socket "/var/run/postgresql/.s.PGSQL.5432"?
[2021-03-03 14:25:53,512] {scheduler_job.py:641} WARNING - No viable dags retrieved from /opt/airflow/dags/submissions_count.py
[2021-03-03 14:25:53,566] {scheduler_job.py:189} INFO - Processing /opt/airflow/dags/submissions_count.py took 0.142 seconds
[2021-03-03 14:25:59,621] {scheduler_job.py:181} INFO - Started process (PID=603) to work on /opt/airflow/dags/submissions_count.py
[2021-03-03 14:25:59,636] {scheduler_job.py:629} INFO - Processing file /opt/airflow/dags/submissions_count.py for tasks to queue
[2021-03-03 14:25:59,661] {logging_mixin.py:103} INFO - [2021-03-03 14:25:59,661] {dagbag.py:440} INFO - Filling up the DagBag from /opt/airflow/dags/submissions_count.py
[2021-03-03 14:25:59,699] {logging_mixin.py:103} INFO - [2021-03-03 14:25:59,697] {dagbag.py:297} ERROR - Failed to import: /opt/airflow/dags/submissions_count.py
Traceback (most recent call last):
  File "/home/airflow/.local/lib/python3.8/site-packages/airflow/models/dagbag.py", line 294, in _load_modules_from_file
    loader.exec_module(new_module)
  File "<frozen importlib._bootstrap_external>", line 783, in exec_module
  File "<frozen importlib._bootstrap>", line 219, in _call_with_frames_removed
  File "/opt/airflow/dags/submissions_count.py", line 43, in <module>
    python_callable=update_mv(),
  File "/opt/airflow/dags/scripts/submissions_count.py", line 5, in update_mv
    conn = psycopg2.connect(dbname=os.getenv("POSTGRES_DB"),
  File "/home/airflow/.local/lib/python3.8/site-packages/psycopg2/__init__.py", line 127, in connect
    conn = _connect(dsn, connection_factory=connection_factory, **kwasync)
psycopg2.OperationalError: could not connect to server: No such file or directory
	Is the server running locally and accepting
	connections on Unix domain socket "/var/run/postgresql/.s.PGSQL.5432"?
[2021-03-03 14:25:59,700] {scheduler_job.py:641} WARNING - No viable dags retrieved from /opt/airflow/dags/submissions_count.py
[2021-03-03 14:25:59,853] {scheduler_job.py:189} INFO - Processing /opt/airflow/dags/submissions_count.py took 0.254 seconds
